Workbook

Sheet Dashboard
A1: GLOVE TRACKER — DASHBOARD
A2: Live summary. Add names on Colleagues, deliveries on Stock, and hand-outs on Issue Log — this page updates by itself. Anyone on their 3rd pair or more is FLAGGED.
B4: SMALL ON HAND | D4: MEDIUM ON HAND | F4: LARGE ON HAND | H4: TOTAL PAIRS ISSUED | J4: FLAGGED PEOPLE
B5: =Stock!D5 -> 0 | D5: =Stock!D6 -> 0 | F5: =Stock!D7 -> 0 | H5: =Stock!C8 -> 0 | J5: =COUNTIF(Colleagues!I5:I204,"FLAG") -> 0
B8: COLLEAGUES LISTED | D8: GIVEN 1 PAIR | F8: GIVEN 2 PAIRS | H8: NOT YET ISSUED | J8: FLAGGED HAND-OUTS
B9: =COUNTA(Colleagues!B5:B204) -> 0 | D9: =COUNTIF(Colleagues!D5:D204,1) -> 0 | F9: =COUNTIF(Colleagues!D5:D204,2) -> 0 | H9: =COUNTIF(Colleagues!I5:I204,"Not issued") -> 0 | J9: =COUNTIF('Issue Log'!G5:G1004,"FLAG") -> 0
B12: Size | C12: Received | D12: Issued | E12: On Hand | F12: Status
B13: =Stock!A5 -> Small | C13: =Stock!B5 -> 0 | D13: =Stock!C5 -> 0 | E13: =Stock!D5 -> 0 | F13: =Stock!E5 -> OUT OF STOCK
B14: =Stock!A6 -> Medium | C14: =Stock!B6 -> 0 | D14: =Stock!C6 -> 0 | E14: =Stock!D6 -> 0 | F14: =Stock!E6 -> OUT OF STOCK
B15: =Stock!A7 -> Large | C15: =Stock!B7 -> 0 | D15: =Stock!C7 -> 0 | E15: =Stock!D7 -> 0 | F15: =Stock!E7 -> OUT OF STOCK
B16: Total | C16: =Stock!B8 -> 0 | D16: =Stock!C8 -> 0 | E16: =Stock!D8 -> 0
B17: ="Low-stock alert below "&Stock!B10&" pairs per size" -> Low-stock alert below 10 pairs per size
B19: HOW TO USE
B20: 1. Colleagues — type each name and pick their glove size (pink cells).
B21: 2. Stock — log every delivery: date, size, pairs received.
B22: 3. Issue Log — each hand-out: date, name (dropdown), size, pairs, reason.
B23: 4. Counts never reset. 1st & 2nd pair = OK; 3rd pair or more = FLAG (red).
B24: Pink cells = type here. White cells = automatic, don't overwrite.
B28: ⚑ FLAGGED — 3rd PAIR OR MORE
B29: # | C29: Name | E29: Size | F29: Total Pairs | G29: 1st Pair | H29: 2nd Pair | I29: 3rd Pair | J29: Last Issued
B30: =IF(1>$J$5,"",1) | C30: =IF(1>$J$5,"",INDEX(Colleagues!$B$5:$B$204,MATCH(1,Colleagues!$J$5:$J$204,0))) | E30: =IF(1>$J$5,"",INDEX(Colleagues!$C$5:$C$204,MATCH(1,Colleagues!$J$5:$J$204,0))) | F30: =IF(1>$J$5,"",INDEX(Colleagues!$D$5:$D$204,MATCH(1,Colleagues!$J$5:$J$204,0))) | G30: =IF(1>$J$5,"",INDEX(Colleagues!$E$5:$E$204,MATCH(1,Colleagues!$J$5:$J$204,0))) | H30: =IF(1>$J$5,"",INDEX(Colleagues!$F$5:$F$204,MATCH(1,Colleagues!$J$5:$J$204,0))) | I30: =IF(1>$J$5,"",INDEX(Colleagues!$G$5:$G$204,MATCH(1,Colleagues!$J$5:$J$204,0))) | J30: =IF(1>$J$5,"",INDEX(Colleagues!$H$5:$H$204,MATCH(1,Colleagues!$J$5:$J$204,0)))
B31: =IF(2>$J$5,"",2) | C31: =IF(2>$J$5,"",INDEX(Colleagues!$B$5:$B$204,MATCH(2,Colleagues!$J$5:$J$204,0))) | E31: =IF(2>$J$5,"",INDEX(Colleagues!$C$5:$C$204,MATCH(2,Colleagues!$J$5:$J$204,0))) | F31: =IF(2>$J$5,"",INDEX(Colleagues!$D$5:$D$204,MATCH(2,Colleagues!$J$5:$J$204,0))) | G31: =IF(2>$J$5,"",INDEX(Colleagues!$E$5:$E$204,MATCH(2,Colleagues!$J$5:$J$204,0))) | H31: =IF(2>$J$5,"",INDEX(Colleagues!$F$5:$F$204,MATCH(2,Colleagues!$J$5:$J$204,0))) | I31: =IF(2>$J$5,"",INDEX(Colleagues!$G$5:$G$204,MATCH(2,Colleagues!$J$5:$J$204,0))) | J31: =IF(2>$J$5,"",INDEX(Colleagues!$H$5:$H$204,MATCH(2,Colleagues!$J$5:$J$204,0)))
B32: =IF(3>$J$5,"",3) | C32: =IF(3>$J$5,"",INDEX(Colleagues!$B$5:$B$204,MATCH(3,Colleagues!$J$5:$J$204,0))) | E32: =IF(3>$J$5,"",INDEX(Colleagues!$C$5:$C$204,MATCH(3,Colleagues!$J$5:$J$204,0))) | F32: =IF(3>$J$5,"",INDEX(Colleagues!$D$5:$D$204,MATCH(3,Colleagues!$J$5:$J$204,0))) | G32: =IF(3>$J$5,"",INDEX(Colleagues!$E$5:$E$204,MATCH(3,Colleagues!$J$5:$J$204,0))) | H32: =IF(3>$J$5,"",INDEX(Colleagues!$F$5:$F$204,MATCH(3,Colleagues!$J$5:$J$204,0))) | I32: =IF(3>$J$5,"",INDEX(Colleagues!$G$5:$G$204,MATCH(3,Colleagues!$J$5:$J$204,0))) | J32: =IF(3>$J$5,"",INDEX(Colleagues!$H$5:$H$204,MATCH(3,Colleagues!$J$5:$J$204,0)))
B33: =IF(4>$J$5,"",4) | C33: =IF(4>$J$5,"",INDEX(Colleagues!$B$5:$B$204,MATCH(4,Colleagues!$J$5:$J$204,0))) | E33: =IF(4>$J$5,"",INDEX(Colleagues!$C$5:$C$204,MATCH(4,Colleagues!$J$5:$J$204,0))) | F33: =IF(4>$J$5,"",INDEX(Colleagues!$D$5:$D$204,MATCH(4,Colleagues!$J$5:$J$204,0))) | G33: =IF(4>$J$5,"",INDEX(Colleagues!$E$5:$E$204,MATCH(4,Colleagues!$J$5:$J$204,0))) | H33: =IF(4>$J$5,"",INDEX(Colleagues!$F$5:$F$204,MATCH(4,Colleagues!$J$5:$J$204,0))) | I33: =IF(4>$J$5,"",INDEX(Colleagues!$G$5:$G$204,MATCH(4,Colleagues!$J$5:$J$204,0))) | J33: =IF(4>$J$5,"",INDEX(Colleagues!$H$5:$H$204,MATCH(4,Colleagues!$J$5:$J$204,0)))
B34: =IF(5>$J$5,"",5) | C34: =IF(5>$J$5,"",INDEX(Colleagues!$B$5:$B$204,MATCH(5,Colleagues!$J$5:$J$204,0))) | E34: =IF(5>$J$5,"",INDEX(Colleagues!$C$5:$C$204,MATCH(5,Colleagues!$J$5:$J$204,0))) | F34: =IF(5>$J$5,"",INDEX(Colleagues!$D$5:$D$204,MATCH(5,Colleagues!$J$5:$J$204,0))) | G34: =IF(5>$J$5,"",INDEX(Colleagues!$E$5:$E$204,MATCH(5,Colleagues!$J$5:$J$204,0))) | H34: =IF(5>$J$5,"",INDEX(Colleagues!$F$5:$F$204,MATCH(5,Colleagues!$J$5:$J$204,0))) | I34: =IF(5>$J$5,"",INDEX(Colleagues!$G$5:$G$204,MATCH(5,Colleagues!$J$5:$J$204,0))) | J34: =IF(5>$J$5,"",INDEX(Colleagues!$H$5:$H$204,MATCH(5,Colleagues!$J$5:$J$204,0)))
B35: =IF(6>$J$5,"",6) | C35: =IF(6>$J$5,"",INDEX(Colleagues!$B$5:$B$204,MATCH(6,Colleagues!$J$5:$J$204,0))) | E35: =IF(6>$J$5,"",INDEX(Colleagues!$C$5:$C$204,MATCH(6,Colleagues!$J$5:$J$204,0))) | F35: =IF(6>$J$5,"",INDEX(Colleagues!$D$5:$D$204,MATCH(6,Colleagues!$J$5:$J$204,0))) | G35: =IF(6>$J$5,"",INDEX(Colleagues!$E$5:$E$204,MATCH(6,Colleagues!$J$5:$J$204,0))) | H35: =IF(6>$J$5,"",INDEX(Colleagues!$F$5:$F$204,MATCH(6,Colleagues!$J$5:$J$204,0))) | I35: =IF(6>$J$5,"",INDEX(Colleagues!$G$5:$G$204,MATCH(6,Colleagues!$J$5:$J$204,0))) | J35: =IF(6>$J$5,"",INDEX(Colleagues!$H$5:$H$204,MATCH(6,Colleagues!$J$5:$J$204,0)))
B36: =IF(7>$J$5,"",7) | C36: =IF(7>$J$5,"",INDEX(Colleagues!$B$5:$B$204,MATCH(7,Colleagues!$J$5:$J$204,0))) | E36: =IF(7>$J$5,"",INDEX(Colleagues!$C$5:$C$204,MATCH(7,Colleagues!$J$5:$J$204,0))) | F36: =IF(7>$J$5,"",INDEX(Colleagues!$D$5:$D$204,MATCH(7,Colleagues!$J$5:$J$204,0))) | G36: =IF(7>$J$5,"",INDEX(Colleagues!$E$5:$E$204,MATCH(7,Colleagues!$J$5:$J$204,0))) | H36: =IF(7>$J$5,"",INDEX(Colleagues!$F$5:$F$204,MATCH(7,Colleagues!$J$5:$J$204,0))) | I36: =IF(7>$J$5,"",INDEX(Colleagues!$G$5:$G$204,MATCH(7,Colleagues!$J$5:$J$204,0))) | J36: =IF(7>$J$5,"",INDEX(Colleagues!$H$5:$H$204,MATCH(7,Colleagues!$J$5:$J$204,0)))
B37: =IF(8>$J$5,"",8) | C37: =IF(8>$J$5,"",INDEX(Colleagues!$B$5:$B$204,MATCH(8,Colleagues!$J$5:$J$204,0))) | E37: =IF(8>$J$5,"",INDEX(Colleagues!$C$5:$C$204,MATCH(8,Colleagues!$J$5:$J$204,0))) | F37: =IF(8>$J$5,"",INDEX(Colleagues!$D$5:$D$204,MATCH(8,Colleagues!$J$5:$J$204,0))) | G37: =IF(8>$J$5,"",INDEX(Colleagues!$E$5:$E$204,MATCH(8,Colleagues!$J$5:$J$204,0))) | H37: =IF(8>$J$5,"",INDEX(Colleagues!$F$5:$F$204,MATCH(8,Colleagues!$J$5:$J$204,0))) | I37: =IF(8>$J$5,"",INDEX(Colleagues!$G$5:$G$204,MATCH(8,Colleagues!$J$5:$J$204,0))) | J37: =IF(8>$J$5,"",INDEX(Colleagues!$H$5:$H$204,MATCH(8,Colleagues!$J$5:$J$204,0)))
B38: =IF(9>$J$5,"",9) | C38: =IF(9>$J$5,"",INDEX(Colleagues!$B$5:$B$204,MATCH(9,Colleagues!$J$5:$J$204,0))) | E38: =IF(9>$J$5,"",INDEX(Colleagues!$C$5:$C$204,MATCH(9,Colleagues!$J$5:$J$204,0))) | F38: =IF(9>$J$5,"",INDEX(Colleagues!$D$5:$D$204,MATCH(9,Colleagues!$J$5:$J$204,0))) | G38: =IF(9>$J$5,"",INDEX(Colleagues!$E$5:$E$204,MATCH(9,Colleagues!$J$5:$J$204,0))) | H38: =IF(9>$J$5,"",INDEX(Colleagues!$F$5:$F$204,MATCH(9,Colleagues!$J$5:$J$204,0))) | I38: =IF(9>$J$5,"",INDEX(Colleagues!$G$5:$G$204,MATCH(9,Colleagues!$J$5:$J$204,0))) | J38: =IF(9>$J$5,"",INDEX(Colleagues!$H$5:$H$204,MATCH(9,Colleagues!$J$5:$J$204,0)))
B39: =IF(10>$J$5,"",10) | C39: =IF(10>$J$5,"",INDEX(Colleagues!$B$5:$B$204,MATCH(10,Colleagues!$J$5:$J$204,0))) | E39: =IF(10>$J$5,"",INDEX(Colleagues!$C$5:$C$204,MATCH(10,Colleagues!$J$5:$J$204,0))) | F39: =IF(10>$J$5,"",INDEX(Colleagues!$D$5:$D$204,MATCH(10,Colleagues!$J$5:$J$204,0))) | G39: =IF(10>$J$5,"",INDEX(Colleagues!$E$5:$E$204,MATCH(10,Colleagues!$J$5:$J$204,0))) | H39: =IF(10>$J$5,"",INDEX(Colleagues!$F$5:$F$204,MATCH(10,Colleagues!$J$5:$J$204,0))) | I39: =IF(10>$J$5,"",INDEX(Colleagues!$G$5:$G$204,MATCH(10,Colleagues!$J$5:$J$204,0))) | J39: =IF(10>$J$5,"",INDEX(Colleagues!$H$5:$H$204,MATCH(10,Colleagues!$J$5:$J$204,0)))
B40: =IF(11>$J$5,"",11) | C40: =IF(11>$J$5,"",INDEX(Colleagues!$B$5:$B$204,MATCH(11,Colleagues!$J$5:$J$204,0))) | E40: =IF(11>$J$5,"",INDEX(Colleagues!$C$5:$C$204,MATCH(11,Colleagues!$J$5:$J$204,0))) | F40: =IF(11>$J$5,"",INDEX(Colleagues!$D$5:$D$204,MATCH(11,Colleagues!$J$5:$J$204,0))) | G40: =IF(11>$J$5,"",INDEX(Colleagues!$E$5:$E$204,MATCH(11,Colleagues!$J$5:$J$204,0))) | H40: =IF(11>$J$5,"",INDEX(Colleagues!$F$5:$F$204,MATCH(11,Colleagues!$J$5:$J$204,0))) | I40: =IF(11>$J$5,"",INDEX(Colleagues!$G$5:$G$204,MATCH(11,Colleagues!$J$5:$J$204,0))) | J40: =IF(11>$J$5,"",INDEX(Colleagues!$H$5:$H$204,MATCH(11,Colleagues!$J$5:$J$204,0)))
B41: =IF(12>$J$5,"",12) | C41: =IF(12>$J$5,"",INDEX(Colleagues!$B$5:$B$204,MATCH(12,Colleagues!$J$5:$J$204,0))) | E41: =IF(12>$J$5,"",INDEX(Colleagues!$C$5:$C$204,MATCH(12,Colleagues!$J$5:$J$204,0))) | F41: =IF(12>$J$5,"",INDEX(Colleagues!$D$5:$D$204,MATCH(12,Colleagues!$J$5:$J$204,0))) | G41: =IF(12>$J$5,"",INDEX(Colleagues!$E$5:$E$204,MATCH(12,Colleagues!$J$5:$J$204,0))) | H41: =IF(12>$J$5,"",INDEX(Colleagues!$F$5:$F$204,MATCH(12,Colleagues!$J$5:$J$204,0))) | I41: =IF(12>$J$5,"",INDEX(Colleagues!$G$5:$G$204,MATCH(12,Colleagues!$J$5:$J$204,0))) | J41: =IF(12>$J$5,"",INDEX(Colleagues!$H$5:$H$204,MATCH(12,Colleagues!$J$5:$J$204,0)))
B42: =IF(13>$J$5,"",13) | C42: =IF(13>$J$5,"",INDEX(Colleagues!$B$5:$B$204,MATCH(13,Colleagues!$J$5:$J$204,0))) | E42: =IF(13>$J$5,"",INDEX(Colleagues!$C$5:$C$204,MATCH(13,Colleagues!$J$5:$J$204,0))) | F42: =IF(13>$J$5,"",INDEX(Colleagues!$D$5:$D$204,MATCH(13,Colleagues!$J$5:$J$204,0))) | G42: =IF(13>$J$5,"",INDEX(Colleagues!$E$5:$E$204,MATCH(13,Colleagues!$J$5:$J$204,0))) | H42: =IF(13>$J$5,"",INDEX(Colleagues!$F$5:$F$204,MATCH(13,Colleagues!$J$5:$J$204,0))) | I42: =IF(13>$J$5,"",INDEX(Colleagues!$G$5:$G$204,MATCH(13,Colleagues!$J$5:$J$204,0))) | J42: =IF(13>$J$5,"",INDEX(Colleagues!$H$5:$H$204,MATCH(13,Colleagues!$J$5:$J$204,0)))
B43: =IF(14>$J$5,"",14) | C43: =IF(14>$J$5,"",INDEX(Colleagues!$B$5:$B$204,MATCH(14,Colleagues!$J$5:$J$204,0))) | E43: =IF(14>$J$5,"",INDEX(Colleagues!$C$5:$C$204,MATCH(14,Colleagues!$J$5:$J$204,0))) | F43: =IF(14>$J$5,"",INDEX(Colleagues!$D$5:$D$204,MATCH(14,Colleagues!$J$5:$J$204,0))) | G43: =IF(14>$J$5,"",INDEX(Colleagues!$E$5:$E$204,MATCH(14,Colleagues!$J$5:$J$204,0))) | H43: =IF(14>$J$5,"",INDEX(Colleagues!$F$5:$F$204,MATCH(14,Colleagues!$J$5:$J$204,0))) | I43: =IF(14>$J$5,"",INDEX(Colleagues!$G$5:$G$204,MATCH(14,Colleagues!$J$5:$J$204,0))) | J43: =IF(14>$J$5,"",INDEX(Colleagues!$H$5:$H$204,MATCH(14,Colleagues!$J$5:$J$204,0)))
B44: =IF(15>$J$5,"",15) | C44: =IF(15>$J$5,"",INDEX(Colleagues!$B$5:$B$204,MATCH(15,Colleagues!$J$5:$J$204,0))) | E44: =IF(15>$J$5,"",INDEX(Colleagues!$C$5:$C$204,MATCH(15,Colleagues!$J$5:$J$204,0))) | F44: =IF(15>$J$5,"",INDEX(Colleagues!$D$5:$D$204,MATCH(15,Colleagues!$J$5:$J$204,0))) | G44: =IF(15>$J$5,"",INDEX(Colleagues!$E$5:$E$204,MATCH(15,Colleagues!$J$5:$J$204,0))) | H44: =IF(15>$J$5,"",INDEX(Colleagues!$F$5:$F$204,MATCH(15,Colleagues!$J$5:$J$204,0))) | I44: =IF(15>$J$5,"",INDEX(Colleagues!$G$5:$G$204,MATCH(15,Colleagues!$J$5:$J$204,0))) | J44: =IF(15>$J$5,"",INDEX(Colleagues!$H$5:$H$204,MATCH(15,Colleagues!$J$5:$J$204,0)))
B45: =IF(16>$J$5,"",16) | C45: =IF(16>$J$5,"",INDEX(Colleagues!$B$5:$B$204,MATCH(16,Colleagues!$J$5:$J$204,0))) | E45: =IF(16>$J$5,"",INDEX(Colleagues!$C$5:$C$204,MATCH(16,Colleagues!$J$5:$J$204,0))) | F45: =IF(16>$J$5,"",INDEX(Colleagues!$D$5:$D$204,MATCH(16,Colleagues!$J$5:$J$204,0))) | G45: =IF(16>$J$5,"",INDEX(Colleagues!$E$5:$E$204,MATCH(16,Colleagues!$J$5:$J$204,0))) | H45: =IF(16>$J$5,"",INDEX(Colleagues!$F$5:$F$204,MATCH(16,Colleagues!$J$5:$J$204,0))) | I45: =IF(16>$J$5,"",INDEX(Colleagues!$G$5:$G$204,MATCH(16,Colleagues!$J$5:$J$204,0))) | J45: =IF(16>$J$5,"",INDEX(Colleagues!$H$5:$H$204,MATCH(16,Colleagues!$J$5:$J$204,0)))
B46: =IF(17>$J$5,"",17) | C46: =IF(17>$J$5,"",INDEX(Colleagues!$B$5:$B$204,MATCH(17,Colleagues!$J$5:$J$204,0))) | E46: =IF(17>$J$5,"",INDEX(Colleagues!$C$5:$C$204,MATCH(17,Colleagues!$J$5:$J$204,0))) | F46: =IF(17>$J$5,"",INDEX(Colleagues!$D$5:$D$204,MATCH(17,Colleagues!$J$5:$J$204,0))) | G46: =IF(17>$J$5,"",INDEX(Colleagues!$E$5:$E$204,MATCH(17,Colleagues!$J$5:$J$204,0))) | H46: =IF(17>$J$5,"",INDEX(Colleagues!$F$5:$F$204,MATCH(17,Colleagues!$J$5:$J$204,0))) | I46: =IF(17>$J$5,"",INDEX(Colleagues!$G$5:$G$204,MATCH(17,Colleagues!$J$5:$J$204,0))) | J46: =IF(17>$J$5,"",INDEX(Colleagues!$H$5:$H$204,MATCH(17,Colleagues!$J$5:$J$204,0)))
B47: =IF(18>$J$5,"",18) | C47: =IF(18>$J$5,"",INDEX(Colleagues!$B$5:$B$204,MATCH(18,Colleagues!$J$5:$J$204,0))) | E47: =IF(18>$J$5,"",INDEX(Colleagues!$C$5:$C$204,MATCH(18,Colleagues!$J$5:$J$204,0))) | F47: =IF(18>$J$5,"",INDEX(Colleagues!$D$5:$D$204,MATCH(18,Colleagues!$J$5:$J$204,0))) | G47: =IF(18>$J$5,"",INDEX(Colleagues!$E$5:$E$204,MATCH(18,Colleagues!$J$5:$J$204,0))) | H47: =IF(18>$J$5,"",INDEX(Colleagues!$F$5:$F$204,MATCH(18,Colleagues!$J$5:$J$204,0))) | I47: =IF(18>$J$5,"",INDEX(Colleagues!$G$5:$G$204,MATCH(18,Colleagues!$J$5:$J$204,0))) | J47: =IF(18>$J$5,"",INDEX(Colleagues!$H$5:$H$204,MATCH(18,Colleagues!$J$5:$J$204,0)))
B48: =IF(19>$J$5,"",19) | C48: =IF(19>$J$5,"",INDEX(Colleagues!$B$5:$B$204,MATCH(19,Colleagues!$J$5:$J$204,0))) | E48: =IF(19>$J$5,"",INDEX(Colleagues!$C$5:$C$204,MATCH(19,Colleagues!$J$5:$J$204,0))) | F48: =IF(19>$J$5,"",INDEX(Colleagues!$D$5:$D$204,MATCH(19,Colleagues!$J$5:$J$204,0))) | G48: =IF(19>$J$5,"",INDEX(Colleagues!$E$5:$E$204,MATCH(19,Colleagues!$J$5:$J$204,0))) | H48: =IF(19>$J$5,"",INDEX(Colleagues!$F$5:$F$204,MATCH(19,Colleagues!$J$5:$J$204,0))) | I48: =IF(19>$J$5,"",INDEX(Colleagues!$G$5:$G$204,MATCH(19,Colleagues!$J$5:$J$204,0))) | J48: =IF(19>$J$5,"",INDEX(Colleagues!$H$5:$H$204,MATCH(19,Colleagues!$J$5:$J$204,0)))
B49: =IF(20>$J$5,"",20) | C49: =IF(20>$J$5,"",INDEX(Colleagues!$B$5:$B$204,MATCH(20,Colleagues!$J$5:$J$204,0))) | E49: =IF(20>$J$5,"",INDEX(Colleagues!$C$5:$C$204,MATCH(20,Colleagues!$J$5:$J$204,0))) | F49: =IF(20>$J$5,"",INDEX(Colleagues!$D$5:$D$204,MATCH(20,Colleagues!$J$5:$J$204,0))) | G49: =IF(20>$J$5,"",INDEX(Colleagues!$E$5:$E$204,MATCH(20,Colleagues!$J$5:$J$204,0))) | H49: =IF(20>$J$5,"",INDEX(Colleagues!$F$5:$F$204,MATCH(20,Colleagues!$J$5:$J$204,0))) | I49: =IF(20>$J$5,"",INDEX(Colleagues!$G$5:$G$204,MATCH(20,Colleagues!$J$5:$J$204,0))) | J49: =IF(20>$J$5,"",INDEX(Colleagues!$H$5:$H$204,MATCH(20,Colleagues!$J$5:$J$204,0)))
...

Sheet Colleagues
A1: COLLEAGUES
A2: Type names in column B and pick each person's glove size in column C (pink cells). Everything else fills in automatically from the Issue Log. 3rd pair or more = FLAG.
A4: # | B4: Name | C4: Glove Size | D4: Total Pairs Given | E4: 1st Pair Date | F4: 2nd Pair Date | G4: 3rd Pair Date | H4: Last Issued | I4: Status | J4: Flag #
A5: 1 | D5: =IF(B5="","",SUMIFS('Issue Log'!$D$5:$D$1004,'Issue Log'!$B$5:$B$1004,B5)) | E5: =IF(OR(B5="",N(D5)<1),"",_xlfn.MINIFS('Issue Log'!$A$5:$A$1004,'Issue Log'!$B$5:$B$1004,B5,'Issue Log'!$F$5:$F$1004,">="&1)) | F5: =IF(OR(B5="",N(D5)<2),"",_xlfn.MINIFS('Issue Log'!$A$5:$A$1004,'Issue Log'!$B$5:$B$1004,B5,'Issue Log'!$F$5:$F$1004,">="&2)) | G5: =IF(OR(B5="",N(D5)<3),"",_xlfn.MINIFS('Issue Log'!$A$5:$A$1004,'Issue Log'!$B$5:$B$1004,B5,'Issue Log'!$F$5:$F$1004,">="&3)) | H5: =IF(N(D5)=0,"",_xlfn.MAXIFS('Issue Log'!$A$5:$A$1004,'Issue Log'!$B$5:$B$1004,B5)) | I5: =IF(B5="","",IF(D5>=3,"FLAG",IF(D5=0,"Not issued","OK"))) | J5: =IF(I5="FLAG",COUNTIF($I$5:I5,"FLAG"),"")
A6: 2 | D6: =IF(B6="","",SUMIFS('Issue Log'!$D$5:$D$1004,'Issue Log'!$B$5:$B$1004,B6)) | E6: =IF(OR(B6="",N(D6)<1),"",_xlfn.MINIFS('Issue Log'!$A$5:$A$1004,'Issue Log'!$B$5:$B$1004,B6,'Issue Log'!$F$5:$F$1004,">="&1)) | F6: =IF(OR(B6="",N(D6)<2),"",_xlfn.MINIFS('Issue Log'!$A$5:$A$1004,'Issue Log'!$B$5:$B$1004,B6,'Issue Log'!$F$5:$F$1004,">="&2)) | G6: =IF(OR(B6="",N(D6)<3),"",_xlfn.MINIFS('Issue Log'!$A$5:$A$1004,'Issue Log'!$B$5:$B$1004,B6,'Issue Log'!$F$5:$F$1004,">="&3)) | H6: =IF(N(D6)=0,"",_xlfn.MAXIFS('Issue Log'!$A$5:$A$1004,'Issue Log'!$B$5:$B$1004,B6)) | I6: =IF(B6="","",IF(D6>=3,"FLAG",IF(D6=0,"Not issued","OK"))) | J6: =IF(I6="FLAG",COUNTIF($I$5:I6,"FLAG"),"")
A7: 3 | D7: =IF(B7="","",SUMIFS('Issue Log'!$D$5:$D$1004,'Issue Log'!$B$5:$B$1004,B7)) | E7: =IF(OR(B7="",N(D7)<1),"",_xlfn.MINIFS('Issue Log'!$A$5:$A$1004,'Issue Log'!$B$5:$B$1004,B7,'Issue Log'!$F$5:$F$1004,">="&1)) | F7: =IF(OR(B7="",N(D7)<2),"",_xlfn.MINIFS('Issue Log'!$A$5:$A$1004,'Issue Log'!$B$5:$B$1004,B7,'Issue Log'!$F$5:$F$1004,">="&2)) | G7: =IF(OR(B7="",N(D7)<3),"",_xlfn.MINIFS('Issue Log'!$A$5:$A$1004,'Issue Log'!$B$5:$B$1004,B7,'Issue Log'!$F$5:$F$1004,">="&3)) | H7: =IF(N(D7)=0,"",_xlfn.MAXIFS('Issue Log'!$A$5:$A$1004,'Issue Log'!$B$5:$B$1004,B7)) | I7: =IF(B7="","",IF(D7>=3,"FLAG",IF(D7=0,"Not issued","OK"))) | J7: =IF(I7="FLAG",COUNTIF($I$5:I7,"FLAG"),"")
A8: 4 | D8: =IF(B8="","",SUMIFS('Issue Log'!$D$5:$D$1004,'Issue Log'!$B$5:$B$1004,B8)) | E8: =IF(OR(B8="",N(D8)<1),"",_xlfn.MINIFS('Issue Log'!$A$5:$A$1004,'Issue Log'!$B$5:$B$1004,B8,'Issue Log'!$F$5:$F$1004,">="&1)) | F8: =IF(OR(B8="",N(D8)<2),"",_xlfn.MINIFS('Issue Log'!$A$5:$A$1004,'Issue Log'!$B$5:$B$1004,B8,'Issue Log'!$F$5:$F$1004,">="&2)) | G8: =IF(OR(B8="",N(D8)<3),"",_xlfn.MINIFS('Issue Log'!$A$5:$A$1004,'Issue Log'!$B$5:$B$1004,B8,'Issue Log'!$F$5:$F$1004,">="&3)) | H8: =IF(N(D8)=0,"",_xlfn.MAXIFS('Issue Log'!$A$5:$A$1004,'Issue Log'!$B$5:$B$1004,B8)) | I8: =IF(B8="","",IF(D8>=3,"FLAG",IF(D8=0,"Not issued","OK"))) | J8: =IF(I8="FLAG",COUNTIF($I$5:I8,"FLAG"),"")
A9: 5 | D9: =IF(B9="","",SUMIFS('Issue Log'!$D$5:$D$1004,'Issue Log'!$B$5:$B$1004,B9)) | E9: =IF(OR(B9="",N(D9)<1),"",_xlfn.MINIFS('Issue Log'!$A$5:$A$1004,'Issue Log'!$B$5:$B$1004,B9,'Issue Log'!$F$5:$F$1004,">="&1)) | F9: =IF(OR(B9="",N(D9)<2),"",_xlfn.MINIFS('Issue Log'!$A$5:$A$1004,'Issue Log'!$B$5:$B$1004,B9,'Issue Log'!$F$5:$F$1004,">="&2)) | G9: =IF(OR(B9="",N(D9)<3),"",_xlfn.MINIFS('Issue Log'!$A$5:$A$1004,'Issue Log'!$B$5:$B$1004,B9,'Issue Log'!$F$5:$F$1004,">="&3)) | H9: =IF(N(D9)=0,"",_xlfn.MAXIFS('Issue Log'!$A$5:$A$1004,'Issue Log'!$B$5:$B$1004,B9)) | I9: =IF(B9="","",IF(D9>=3,"FLAG",IF(D9=0,"Not issued","OK"))) | J9: =IF(I9="FLAG",COUNTIF($I$5:I9,"FLAG"),"")
A10: 6 | D10: =IF(B10="","",SUMIFS('Issue Log'!$D$5:$D$1004,'Issue Log'!$B$5:$B$1004,B10)) | E10: =IF(OR(B10="",N(D10)<1),"",_xlfn.MINIFS('Issue Log'!$A$5:$A$1004,'Issue Log'!$B$5:$B$1004,B10,'Issue Log'!$F$5:$F$1004,">="&1)) | F10: =IF(OR(B10="",N(D10)<2),"",_xlfn.MINIFS('Issue Log'!$A$5:$A$1004,'Issue Log'!$B$5:$B$1004,B10,'Issue Log'!$F$5:$F$1004,">="&2)) | G10: =IF(OR(B10="",N(D10)<3),"",_xlfn.MINIFS('Issue Log'!$A$5:$A$1004,'Issue Log'!$B$5:$B$1004,B10,'Issue Log'!$F$5:$F$1004,">="&3)) | H10: =IF(N(D10)=0,"",_xlfn.MAXIFS('Issue Log'!$A$5:$A$1004,'Issue Log'!$B$5:$B$1004,B10)) | I10: =IF(B10="","",IF(D10>=3,"FLAG",IF(D10=0,"Not issued","OK"))) | J10: =IF(I10="FLAG",COUNTIF($I$5:I10,"FLAG"),"")
A11: 7 | D11: =IF(B11="","",SUMIFS('Issue Log'!$D$5:$D$1004,'Issue Log'!$B$5:$B$1004,B11)) | E11: =IF(OR(B11="",N(D11)<1),"",_xlfn.MINIFS('Issue Log'!$A$5:$A$1004,'Issue Log'!$B$5:$B$1004,B11,'Issue Log'!$F$5:$F$1004,">="&1)) | F11: =IF(OR(B11="",N(D11)<2),"",_xlfn.MINIFS('Issue Log'!$A$5:$A$1004,'Issue Log'!$B$5:$B$1004,B11,'Issue Log'!$F$5:$F$1004,">="&2)) | G11: =IF(OR(B11="",N(D11)<3),"",_xlfn.MINIFS('Issue Log'!$A$5:$A$1004,'Issue Log'!$B$5:$B$1004,B11,'Issue Log'!$F$5:$F$1004,">="&3)) | H11: =IF(N(D11)=0,"",_xlfn.MAXIFS('Issue Log'!$A$5:$A$1004,'Issue Log'!$B$5:$B$1004,B11)) | I11: =IF(B11="","",IF(D11>=3,"FLAG",IF(D11=0,"Not issued","OK"))) | J11: =IF(I11="FLAG",COUNTIF($I$5:I11,"FLAG"),"")
A12: 8 | D12: =IF(B12="","",SUMIFS('Issue Log'!$D$5:$D$1004,'Issue Log'!$B$5:$B$1004,B12)) | E12: =IF(OR(B12="",N(D12)<1),"",_xlfn.MINIFS('Issue Log'!$A$5:$A$1004,'Issue Log'!$B$5:$B$1004,B12,'Issue Log'!$F$5:$F$1004,">="&1)) | F12: =IF(OR(B12="",N(D12)<2),"",_xlfn.MINIFS('Issue Log'!$A$5:$A$1004,'Issue Log'!$B$5:$B$1004,B12,'Issue Log'!$F$5:$F$1004,">="&2)) | G12: =IF(OR(B12="",N(D12)<3),"",_xlfn.MINIFS('Issue Log'!$A$5:$A$1004,'Issue Log'!$B$5:$B$1004,B12,'Issue Log'!$F$5:$F$1004,">="&3)) | H12: =IF(N(D12)=0,"",_xlfn.MAXIFS('Issue Log'!$A$5:$A$1004,'Issue Log'!$B$5:$B$1004,B12)) | I12: =IF(B12="","",IF(D12>=3,"FLAG",IF(D12=0,"Not issued","OK"))) | J12: =IF(I12="FLAG",COUNTIF($I$5:I12,"FLAG"),"")
A13: 9 | D13: =IF(B13="","",SUMIFS('Issue Log'!$D$5:$D$1004,'Issue Log'!$B$5:$B$1004,B13)) | E13: =IF(OR(B13="",N(D13)<1),"",_xlfn.MINIFS('Issue Log'!$A$5:$A$1004,'Issue Log'!$B$5:$B$1004,B13,'Issue Log'!$F$5:$F$1004,">="&1)) | F13: =IF(OR(B13="",N(D13)<2),"",_xlfn.MINIFS('Issue Log'!$A$5:$A$1004,'Issue Log'!$B$5:$B$1004,B13,'Issue Log'!$F$5:$F$1004,">="&2)) | G13: =IF(OR(B13="",N(D13)<3),"",_xlfn.MINIFS('Issue Log'!$A$5:$A$1004,'Issue Log'!$B$5:$B$1004,B13,'Issue Log'!$F$5:$F$1004,">="&3)) | H13: =IF(N(D13)=0,"",_xlfn.MAXIFS('Issue Log'!$A$5:$A$1004,'Issue Log'!$B$5:$B$1004,B13)) | I13: =IF(B13="","",IF(D13>=3,"FLAG",IF(D13=0,"Not issued","OK"))) | J13: =IF(I13="FLAG",COUNTIF($I$5:I13,"FLAG"),"")
A14: 10 | D14: =IF(B14="","",SUMIFS('Issue Log'!$D$5:$D$1004,'Issue Log'!$B$5:$B$1004,B14)) | E14: =IF(OR(B14="",N(D14)<1),"",_xlfn.MINIFS('Issue Log'!$A$5:$A$1004,'Issue Log'!$B$5:$B$1004,B14,'Issue Log'!$F$5:$F$1004,">="&1)) | F14: =IF(OR(B14="",N(D14)<2),"",_xlfn.MINIFS('Issue Log'!$A$5:$A$1004,'Issue Log'!$B$5:$B$1004,B14,'Issue Log'!$F$5:$F$1004,">="&2)) | G14: =IF(OR(B14="",N(D14)<3),"",_xlfn.MINIFS('Issue Log'!$A$5:$A$1004,'Issue Log'!$B$5:$B$1004,B14,'Issue Log'!$F$5:$F$1004,">="&3)) | H14: =IF(N(D14)=0,"",_xlfn.MAXIFS('Issue Log'!$A$5:$A$1004,'Issue Log'!$B$5:$B$1004,B14)) | I14: =IF(B14="","",IF(D14>=3,"FLAG",IF(D14=0,"Not issued","OK"))) | J14: =IF(I14="FLAG",COUNTIF($I$5:I14,"FLAG"),"")
A15: 11 | D15: =IF(B15="","",SUMIFS('Issue Log'!$D$5:$D$1004,'Issue Log'!$B$5:$B$1004,B15)) | E15: =IF(OR(B15="",N(D15)<1),"",_xlfn.MINIFS('Issue Log'!$A$5:$A$1004,'Issue Log'!$B$5:$B$1004,B15,'Issue Log'!$F$5:$F$1004,">="&1)) | F15: =IF(OR(B15="",N(D15)<2),"",_xlfn.MINIFS('Issue Log'!$A$5:$A$1004,'Issue Log'!$B$5:$B$1004,B15,'Issue Log'!$F$5:$F$1004,">="&2)) | G15: =IF(OR(B15="",N(D15)<3),"",_xlfn.MINIFS('Issue Log'!$A$5:$A$1004,'Issue Log'!$B$5:$B$1004,B15,'Issue Log'!$F$5:$F$1004,">="&3)) | H15: =IF(N(D15)=0,"",_xlfn.MAXIFS('Issue Log'!$A$5:$A$1004,'Issue Log'!$B$5:$B$1004,B15)) | I15: =IF(B15="","",IF(D15>=3,"FLAG",IF(D15=0,"Not issued","OK"))) | J15: =IF(I15="FLAG",COUNTIF($I$5:I15,"FLAG"),"")
A16: 12 | D16: =IF(B16="","",SUMIFS('Issue Log'!$D$5:$D$1004,'Issue Log'!$B$5:$B$1004,B16)) | E16: =IF(OR(B16="",N(D16)<1),"",_xlfn.MINIFS('Issue Log'!$A$5:$A$1004,'Issue Log'!$B$5:$B$1004,B16,'Issue Log'!$F$5:$F$1004,">="&1)) | F16: =IF(OR(B16="",N(D16)<2),"",_xlfn.MINIFS('Issue Log'!$A$5:$A$1004,'Issue Log'!$B$5:$B$1004,B16,'Issue Log'!$F$5:$F$1004,">="&2)) | G16: =IF(OR(B16="",N(D16)<3),"",_xlfn.MINIFS('Issue Log'!$A$5:$A$1004,'Issue Log'!$B$5:$B$1004,B16,'Issue Log'!$F$5:$F$1004,">="&3)) | H16: =IF(N(D16)=0,"",_xlfn.MAXIFS('Issue Log'!$A$5:$A$1004,'Issue Log'!$B$5:$B$1004,B16)) | I16: =IF(B16="","",IF(D16>=3,"FLAG",IF(D16=0,"Not issued","OK"))) | J16: =IF(I16="FLAG",COUNTIF($I$5:I16,"FLAG"),"")
... A204: 200 | D204: =IF(B204="","",SUMIFS('Issue Log'!$D$5:$D$1004,'Issue Log'!$B$5:$B$1004,B204)) | E204: =IF(OR(B204="",N(D204)<1),"",_xlfn.MINIFS('Issue Log'!$A$5:$A$1004,'Issue Log'!$B$5:$B$1004,B204,'Issue Log'!$F$5:$F$1004,">="&1)) | F204: =IF(OR(B204="",N(D204)<2),"",_xlfn.MINIFS('Issue Log'!$A$5:$A$1004,'Issue Log'!$B$5:$B$1004,B204,'Issue Log'!$F$5:$F$1004,">="&2)) | G204: =IF(OR(B204="",N(D204)<3),"",_xlfn.MINIFS('Issue Log'!$A$5:$A$1004,'Issue Log'!$B$5:$B$1004,B204,'Issue Log'!$F$5:$F$1004,">="&3)) | H204: =IF(N(D204)=0,"",_xlfn.MAXIFS('Issue Log'!$A$5:$A$1004,'Issue Log'!$B$5:$B$1004,B204)) | I204: =IF(B204="","",IF(D204>=3,"FLAG",IF(D204=0,"Not issued","OK"))) | J204: =IF(I204="FLAG",COUNTIF($I$5:I204,"FLAG"),"")

Sheet Issue Log
A1: ISSUE LOG
A2: One row each time gloves are handed out, entered in date order. Fill the pink cells: Date, Name (dropdown from Colleagues), Size, Pairs, Reason. Pair # and Flag are automatic.
A4: Date Given | B4: Name | C4: Size | D4: Pairs Given | E4: Reason / Notes | F4: Pair # (running total) | G4: Flag
F5: =IF(B5="","",SUMIFS($D$5:D5,$B$5:B5,B5)) | G5: =IF(B5="","",IF(F5>=3,"FLAG",""))
F6: =IF(B6="","",SUMIFS($D$5:D6,$B$5:B6,B6)) | G6: =IF(B6="","",IF(F6>=3,"FLAG",""))
F7: =IF(B7="","",SUMIFS($D$5:D7,$B$5:B7,B7)) | G7: =IF(B7="","",IF(F7>=3,"FLAG",""))
F8: =IF(B8="","",SUMIFS($D$5:D8,$B$5:B8,B8)) | G8: =IF(B8="","",IF(F8>=3,"FLAG",""))
F9: =IF(B9="","",SUMIFS($D$5:D9,$B$5:B9,B9)) | G9: =IF(B9="","",IF(F9>=3,"FLAG",""))
F10: =IF(B10="","",SUMIFS($D$5:D10,$B$5:B10,B10)) | G10: =IF(B10="","",IF(F10>=3,"FLAG",""))
F11: =IF(B11="","",SUMIFS($D$5:D11,$B$5:B11,B11)) | G11: =IF(B11="","",IF(F11>=3,"FLAG",""))
F12: =IF(B12="","",SUMIFS($D$5:D12,$B$5:B12,B12)) | G12: =IF(B12="","",IF(F12>=3,"FLAG",""))
F13: =IF(B13="","",SUMIFS($D$5:D13,$B$5:B13,B13)) | G13: =IF(B13="","",IF(F13>=3,"FLAG",""))
F14: =IF(B14="","",SUMIFS($D$5:D14,$B$5:B14,B14)) | G14: =IF(B14="","",IF(F14>=3,"FLAG",""))
F15: =IF(B15="","",SUMIFS($D$5:D15,$B$5:B15,B15)) | G15: =IF(B15="","",IF(F15>=3,"FLAG",""))
F16: =IF(B16="","",SUMIFS($D$5:D16,$B$5:B16,B16)) | G16: =IF(B16="","",IF(F16>=3,"FLAG",""))
... F1004: =IF(B1004="","",SUMIFS($D$5:D1004,$B$5:B1004,B1004)) | G1004: =IF(B1004="","",IF(F1004>=3,"FLAG",""))

Sheet Stock
A1: STOCK
A2: Record every delivery of gloves in the Deliveries table (pink cells). On Hand = Received − Issued, worked out automatically.
A4: Size | B4: Received | C4: Issued | D4: On Hand | E4: Status
A5: Small | B5: =SUMIFS($C$13:$C$312,$B$13:$B$312,A5) -> 0 | C5: =SUMIFS('Issue Log'!$D$5:$D$1004,'Issue Log'!$C$5:$C$1004,A5) -> 0 | D5: =B5-C5 -> 0 | E5: =IF(D5<=0,"OUT OF STOCK",IF(D5<$B$10,"LOW","OK")) -> OUT OF STOCK
A6: Medium | B6: =SUMIFS($C$13:$C$312,$B$13:$B$312,A6) -> 0 | C6: =SUMIFS('Issue Log'!$D$5:$D$1004,'Issue Log'!$C$5:$C$1004,A6) -> 0 | D6: =B6-C6 -> 0 | E6: =IF(D6<=0,"OUT OF STOCK",IF(D6<$B$10,"LOW","OK")) -> OUT OF STOCK
A7: Large | B7: =SUMIFS($C$13:$C$312,$B$13:$B$312,A7) -> 0 | C7: =SUMIFS('Issue Log'!$D$5:$D$1004,'Issue Log'!$C$5:$C$1004,A7) -> 0 | D7: =B7-C7 -> 0 | E7: =IF(D7<=0,"OUT OF STOCK",IF(D7<$B$10,"LOW","OK")) -> OUT OF STOCK
A8: Total | B8: =SUM(B5:B7) -> 0 | C8: =SUM(C5:C7) -> 0 | D8: =SUM(D5:D7) -> 0
A10: Low-stock alert below | B10: 10 | C10: pairs per size (agreed default — change as needed)
A12: Date Received | B12: Size | C12: Pairs Received | D12: Supplier / Notes
